---
title: "Finally Block"
date: "02/13/2024"
categories: [ basic ]
---


The Python `finally` block is a powerful tool often overlooked, yet it ensures clean code and prevents resource leaks. Unlike `try` and `except` which handle exceptions, `finally` guarantees the execution of a specific block of code regardless of whether an exception occurred or not. This makes it useful for tasks like closing files, releasing network connections, or cleaning up temporary resources.

## Understanding the `try...except...finally` Structure

The basic structure looks like this:


```python
try:
    # Code that might raise an exception
    result = 10 / 0  # This will cause a ZeroDivisionError
except ZeroDivisionError:
    print("Error: Division by zero!")
finally:
    print("This always executes!")
```

In this example, the `try` block attempts a division by zero, resulting in a `ZeroDivisionError`. The `except` block catches this specific error and prints an error message.  Crucially, the `finally` block executes *after* the `except` block (or after the `try` block if no exception occurred), printing "This always executes!"  This ensures that this statement is always printed, even if an error happens.


## Practical Applications of `finally`

The true power of `finally` becomes evident in scenarios involving resource management. Let's look at an example with file handling:


```python
file_handle = None
try:
    file_handle = open("my_file.txt", "r")
    contents = file_handle.read()
    # Process the file contents
    print(contents)
except FileNotFoundError:
    print("File not found!")
finally:
    if file_handle:
        file_handle.close()
        print("File closed successfully!")
```

Here, we open a file.  If the file is successfully opened and processed, or if a `FileNotFoundError` occurs, the `finally` block ensures that the file is closed using `file_handle.close()`. This prevents resource leaks and ensures that the file is properly released, even in the event of an error.


##  `finally` with `return` Statements


The behavior of `finally` with `return` statements is a common source of confusion.  The `finally` block *always* executes before the function returns, even if a `return` statement is encountered within the `try` or `except` block. Consider this:


```python
def my_function():
    try:
        return 10
    finally:
        print("Finally block executed!")
        return 20

result = my_function()
print(result) # Output: 20
```

Notice that even though the `try` block has a `return 10`, the value returned is 20 because the `finally` block's `return` statement overwrites the initial return value.


##  Beyond File Handling:  Wider Use Cases

The `finally` block is not limited to file operations.  Any cleanup action required regardless of success or failure is a good candidate for a `finally` block. This includes:

* **Releasing network connections:** Close sockets or database connections.
* **Unlocking mutexes or semaphores:**  Prevent deadlocks.
* **Cleaning up temporary files or directories:** Delete temporary files created during processing.
* **Restoring system state:** Roll back changes if an error occurs.

By strategically using the `finally` block, you can write reliable Python code, minimizing potential errors and resource leaks.

